Workbook

Sheet 원가계산서 
A1: 역촌동 36-9
A2: 비 목 | D2: 금 액 | E2: 구 성 내 역 | F2: 구성비(%) | G2: 전회까지기성 | H2: 금회기성 | I2: 기성누계 | J2: 기성잔액 | K2: 비 고 | L2: 적용
A3: 순공사원가 | B3: 자재비 | C3: 직접자재비 | D3: =+전체집계!F18 -> 5.4483916e+08
C4: 간접자재비
C5: 소 계 | D5: =SUM(D3:D4) -> 5.4483916e+08 | F5: =IF(D5>0,D5/D23,) -> 0.4656745
B6: 노무비 | C6: 직접노무비 | D6: =+전체집계!H18 -> 4.0008059e+08
C7: 간접노무비 | D7: =D6*L7 -> 20004029 | E7: ="직접노무비의 "&TEXT(L7,"#0.00%") -> 직접노무비의 5.00% | L7: 0.05
C8: 소계 | D8: =SUM(D6:D7) -> 4.2008462e+08 | F8: =IF(D8>0,D8/D23,) -> 0.35904668
B9: 경비 | C9: 운반비 | D9: =TRUNC(D5*L9) -> 0 | E9: ="자재비의 "&TEXT(L9,"#0.00%") -> 자재비의 0.00%
C10: 기계경비 | D10: =+전체집계!J18 -> 85645003
C11: 산재보험료 | D11: =TRUNC(D8*L11) -> 15963215 | E11: ="노무비의 "&TEXT(L11,"#0.00%") -> 노무비의 3.80% | L11: 0.038
C12: 고용보험료 | D12: =TRUNC(D8*L12) -> 3654736 | E12: ="노무비의 "&TEXT(L12,"#0.00%") -> 노무비의 0.87% | L12: 0.0087
C13: 건강보험료 | D13: =TRUNC(D6*L13) -> 12922603 | E13: ="직접노무비의 "&TEXT(L13,"#0.00%") -> 직접노무비의 3.23% | L13: 0.0323
C14: 연금보험료 | D14: =TRUNC(D6*L14) -> 18003626 | E14: ="직접노무비의 "&TEXT(L14,"#0.00%") -> 직접노무비의 4.50% | L14: 0.045
C15: 퇴직공제부금비 | E15: ="직접노무비의 "&TEXT(L15,"#0.00%") -> 직접노무비의 2.30% | K15: 100억 이상 | L15: 0.023 | N15: 73feel@naver.com
C16: 안전관리비 | D16: =(TRUNC((D5+D6)*L16)) -> 18614919 | L16: 0.0197
C17: 기타경비 | D17: =(D5+D8)*L17 -> 4824618.9 | E17: ="자재비+노무비의 "&TEXT(L17,"#0.00%")&"" -> 자재비+노무비의 0.50% | L17: 0.005
C18: 소계 | D18: =SUM(D9:D17) -> 1.5962872e+08 | F18: =IF(D18>0,D18/D23,) -> 0.1364348
B19: 합계 | D19: =D5+D8+D18 -> 1.1245525e+09 | F19: =F5+F8+F18 -> 0.96115598
A20: 간접공사비 | B20: 일반관리비 | D20: =TRUNC(D19*L20) -> 33736574 | E20: ="순공사비의 "&TEXT(L20,"#0.00%") -> 순공사비의 3.00% | F20: =IF(D20>0,D20/D23,) -> 0.028834679 | L20: 0.03
B21: 이윤 | D21: =TRUNC((D8+D18+D20)*L21)-558071 -> 11710927 | E21: ="노무비+경비+일반관리비의 "&TEXT(L21,"#0.00%") -> 노무비+경비+일반관리비의 2.00% | F21: =IF(D21>0,D21/D23,) -> 0.010009339 | L21: 0.02
B22: 소계 | D22: =SUM(D20:D21) -> 45447501 | F22: =SUM(F20:F21) -> 0.038844018
A23: 공사비 합계 | D23: =TRUNC(D22+D19)+E22 -> 1170000000 | F23: =(F5+F8+F18+F22) -> 1 | K23: 십만단위이하절사
A24: 부가세 | D24: =+D23*0.1 -> 117000000 | L24: 0.1
A25: 총공사비계 | D25: =+D24+D23 -> 1287000000 | E25: 부가세포함
D29: 610.41
D30: =+D29*0.3025 -> 184.64902
D31: =+D23/D30 -> 6336345.4
D32: =+D25/D30 -> 6969979.9

Sheet 전체집계
A1: 총 괄 집 계 표
A3: 품 명 | B3: 규 격 | C3: 단위 | D3: 수량 | E3: 재 료 비 | G3: 노 무 비 | I3: 경 비 | K3: 합 계 | M3: 비고
E4: 단가 | F4: 금액 | G4: 단가 | H4: 금액 | I4: 단가 | J4: 금액 | K4: 단가 | L4: 금액
A5: 01 건축공사 | C5: 식 | D5: 1 | F5: =+건축집계!F24 -> 4.1676975e+08 | H5: =+건축집계!H24 -> 2.9765779e+08 | J5: =+건축집계!J24 -> 85645003 | L5: =+J5+H5+F5 -> 8.0007255e+08
A6: 02 기계공사 | C6: 식 | D6: 1 | F6: =+설비집계표!F27 -> 94561172 | H6: =+설비집계표!H27 -> 62057095 | J6: =+설비집계표!K27 -> 0 | L6: =+J6+H6+F6 -> 156618267
A7: 03 전기공사 | C7: 식 | D7: 1 | F7: =+전기총괄표!F20 -> 33508237 | H7: =+전기총괄표!H20 -> 40365700 | J7: =+전기총괄표!J20 -> 0 | L7: =+J7+H7+F7 -> 73873937
L10: =+J10+H10+F10 -> 0
L11: =+J11+H11+F11 -> 0
L12: =+J12+H12+F12 -> 0
A18: [ 합 계 ] | F18: =SUM(F5:F7) -> 5.4483916e+08 | H18: =SUM(H5:H7) -> 4.0008059e+08 | J18: =SUM(J5:J7) -> 85645003 | L18: =SUM(L5:L7) -> 1.0305648e+09
A19: End Of File(Ver 6.0)
A20: 마지막열은 지우지 마시오

Sheet 건축집계
A1: 건 축 집 계 표
A2: =+전체집계!A2 -> 0
A3: 품 명 | B3: 규 격 | C3: 단위 | D3: 수량 | E3: 재 료 비 | G3: 노 무 비 | I3: 경 비 | K3: 합 계 | M3: 비고
E4: 단가 | F4: 금액 | G4: 단가 | H4: 금액 | I4: 단가 | J4: 금액 | K4: 단가 | L4: 금액
A5: 01. 건축공사 | N5: 0101
A6: =건축내역서!C4 -> 0101 가 설 공 사 | C6: 식 | D6: 1 | F6: =건축내역서!H51 -> 17202500 | H6: =건축내역서!J51 -> 22726800 | J6: =건축내역서!L51 -> 25236900 | L6: =+F6+H6+J6 -> 65166200 | N6: 010101
A7: =+건축내역서!C52 -> 0102 구조 보강 공사 (Dr. M PILE) | C7: 식 | D7: 1 | F7: =+건축내역서!H75 -> 23386000 | H7: =+건축내역서!J75 -> 30181600 | J7: =+건축내역서!L75 -> 23752800 | L7: =+F7+H7+J7 -> 77320400
A8: =+건축내역서!C76 -> 0103 철 근 콘 크 리 트 공 사 | C8: 식 | D8: 1 | F8: =+건축내역서!H123 -> 51439058 | H8: =+건축내역서!J123 -> 37710821 | J8: =+건축내역서!L123 -> 4717859.8 | L8: =+F8+H8+J8 -> 93867738 | N8: 010105
A9: =+건축내역서!C124 -> 0104 철 골 공 사 | C9: 식 | D9: 1 | F9: =+건축내역서!H195 -> 76415392 | H9: =+건축내역서!J195 -> 47736674 | J9: =+건축내역서!L195 -> 10750443 | L9: =+J9+H9+F9 -> 1.3490251e+08
A10: =건축내역서!C196 -> 0105 습식공사 (조적, 미장, 방, 타일) | C10: 식 | D10: 1 | F10: =건축내역서!H243 -> 19659600 | H10: =건축내역서!J243 -> 22843200 | J10: =건축내역서!L243 -> 0 | L10: =+F10+H10+J10 -> 42502800 | N10: 010108
A11: =+건축내역서!C244 -> 0106 석 공 사 | C11: 식 | D11: 1 | F11: =+건축내역서!H267 -> 43786600 | H11: =+건축내역서!J267 -> 36940900 | J11: =+건축내역서!L267 -> 12526000 | L11: =+F11+H11+J11 -> 93253500
A12: =+건축내역서!C268 -> 0107 금 속 공 사 | C12: 식 | D12: 1 | F12: =+건축내역서!H291 -> 42651900 | H12: =+건축내역서!J291 -> 31476100 | J12: =+건축내역서!L291 -> 1139700 | L12: =+F12+H12+J12 -> 75267700
A13: =+건축내역서!C292 -> 0108 창 호 공 사 | C13: 식 | D13: 1 | F13: =+건축내역서!H339 -> 43955400 | H13: =+건축내역서!J339 -> 9764000 | J13: =+건축내역서!L339 -> 2267700 | L13: =+F13+H13+J13 -> 55987100
A14: =+건축내역서!C340 -> 0109 유 리 공 사 | C14: 식 | D14: 1 | F14: =+건축내역서!H363 -> 26792300 | H14: =+건축내역서!J363 -> 17045700 | J14: =+건축내역서!L363 -> 2092700 | L14: =+F14+H14+J14 -> 45930700
A15: =+건축내역서!C364 -> 0110 수장, 도장 공사 | C15: 식 | D15: 1 | F15: =+건축내역서!H387 -> 23959700 | H15: =+건축내역서!J387 -> 34575500 | J15: =+건축내역서!L387 -> 816700 | L15: =+F15+H15+J15 -> 59351900
A16: =건축내역서!C388 -> 0111 부 대 토 목 공 사 | C16: 식 | D16: 1 | F16: =건축내역서!H411 -> 47521300 | H16: =건축내역서!J411 -> 6656500 | J16: =건축내역서!L411 -> 2344200 | L16: =+F16+H16+J16 -> 56522000
A24: [ 합 계 ] | F24: =SUM(F6:F23) -> 4.1676975e+08 | H24: =SUM(H6:H23) -> 2.9765779e+08 | J24: =SUM(J6:J23) -> 85645003 | L24: =F24+H24+J24 -> 8.0007255e+08
A25: End Of File(Ver 6.0)
A26: 마지막열은 지우지 마시오

Sheet 건축내역서
C1: =+전체집계!A2 -> 0
A2: 공종 | B2: 코드 | C2: 품 명 | D2: 규 격 | E2: 단위 | F2: 수 량 | G2: 재 료 비 | I2: 노 무 비 | K2: 경 비 | M2: 합 계 | O2: 비고
G3: 단가 | H3: 금 액 | I3: 단가 | J3: 금 액 | K3: 단가 | L3: 금 액 | M3: 단가 | N3: 금 액
C4: 0101 가 설 공 사
A5: 010101 | B5: 91AA0002 | C5: 콘테이너 가설건물 | D5: 3000*6000 | E5: EA | F5: 1 | H5: =F5*G5 -> 0 | J5: =F5*I5 -> 0 | K5: 2914100 | L5: =F5*K5 -> 2914100 | M5: =+G5+I5+K5 -> 2914100 | N5: =+H5+J5+L5 -> 2914100
C6: 장비사용료 | E6: 월 | F6: 6 | H6: =F6*G6 -> 0 | J6: =F6*I6 -> 0 | K6: 999100 | L6: =F6*K6 -> 5994600 | M6: =+G6+I6+K6 -> 999100 | N6: =+H6+J6+L6 -> 5994600
C7: 가설울타리/RPP방음벽 | D7: H 3.0 | E7: M2 | F7: 53 | G7: 15000 | H7: =F7*G7 -> 795000 | I7: 14600 | J7: =F7*I7 -> 773800 | K7: 5400 | L7: =F7*K7 -> 286200 | M7: =+G7+I7+K7 -> 35000 | N7: =+H7+J7+L7 -> 1855000
A8: 010101 | B8: 91BA0111 | C8: 경계 및 준공 측량비 | E8: 식 | F8: 1 | H8: =F8*G8 -> 0 | J8: =F8*I8 -> 0 | K8: 1248900 | L8: =F8*K8 -> 1248900 | M8: =+G8+I8+K8 -> 1248900 | N8: =+H8+J8+L8 -> 1248900
A9: 010101 | B9: 91BA0120 | C9: 가설전기 설치비 | E9: 식 | F9: 1 | H9: =F9*G9 -> 0 | J9: =F9*I9 -> 0 | K9: 1165700 | L9: =F9*K9 -> 1165700 | M9: =+G9+I9+K9 -> 1165700 | N9: =+H9+J9+L9 -> 1165700
A10: 010101 | B10: 91BA0111 | C10: 가설용수 설치비 | E10: 식 | F10: 1 | G10: 83300 | H10: =F10*G10 -> 83300 | I10: 333000 | J10: =F10*I10 -> 333000 | L10: =F10*K10 -> 0 | M10: =+G10+I10+K10 -> 416300 | N10: =+H10+J10+L10 -> 416300
A11: 010101 | B11: 91BA0120 | C11: 가설전기 사용료 | E11: 월 | F11: 6 | H11: =F11*G11 -> 0 | J11: =F11*I11 -> 0 | K11: 208200 | L11: =F11*K11 -> 1249200 | M11: =+G11+I11+K11 -> 208200 | N11: =+H11+J11+L11 -> 1249200
C12: 가설용수 사용료 | E12: 월 | F12: 6 | H12: =F12*G12 -> 0 | J12: =F12*I12 -> 0 | K12: 66600 | L12: =F12*K12 -> 399600 | M12: =+G12+I12+K12 -> 66600 | N12: =+H12+J12+L12 -> 399600
A13: 010101 | B13: 91BA0202 | C13: 잡자재 구입비 | E13: M2 | F13: 632 | G13: 3700 | H13: =F13*G13 -> 2338400 | J13: =F13*I13 -> 0 | L13: =F13*K13 -> 0 | M13: =+G13+I13+K13 -> 3700 | N13: =+H13+J13+L13 -> 2338400
A14: 010101 | B14: 91BA0210 | C14: 폐기물처리비 | E14: M2 | F14: 632 | H14: =F14*G14 -> 0 | J14: =F14*I14 -> 0 | K14: 3100 | L14: =F14*K14 -> 1959200 | M14: =+G14+I14+K14 -> 3100 | N14: =+H14+J14+L14 -> 1959200
C15: 우, 오수 CCTV | D15: 기존 침전물 제거 별도 | E15: 식 | F15: 1 | H15: =F15*G15 -> 0 | J15: =F15*I15 -> 0 | K15: 1248900 | L15: =F15*K15 -> 1248900 | M15: =+G15+I15+K15 -> 1248900 | N15: =+H15+J15+L15 -> 1248900
C16: 도로복구비 | D16: 공사용 진입도로(인도포함) | E16: 식 | F16: 1 | H16: =F16*G16 -> 0 | J16: =F16*I16 -> 0 | K16: 3247200 | L16: =F16*K16 -> 3247200 | M16: =+G16+I16+K16 -> 3247200 | N16: =+H16+J16+L16 -> 3247200
A17: 010101 | B17: 91BA0330 | C17: 현장정리비 | D17: 마감 | E17: M2 | F17: 632 | H17: =F17*G17 -> 0 | I17: 2300 | J17: =F17*I17 -> 1453600 | L17: =F17*K17 -> 0 | M17: =+G17+I17+K17 -> 2300 | N17: =+H17+J17+L17 -> 1453600
A18: 010101 | B18: 91BA0400 | C18: 이동식화장실 | E18: EA | F18: 1 | H18: =F18*G18 -> 0 | J18: =F18*I18 -> 0 | K18: 249800 | L18: =F18*K18 -> 249800 | M18: =+G18+I18+K18 -> 249800 | N18: =+H18+J18+L18 -> 249800
C19: 세륜시설 | E19: 식 | F19: 1 | H19: =F19*G19 -> 0 | J19: =F19*I19 -> 0 | K19: 1498700 | L19: =F19*K19 -> 1498700 | M19: =+G19+I19+K19 -> 1498700 | N19: =+H19+J19+L19 -> 1498700
C20: 준공청소비 | E20: M2 | F20: 632 | H20: =F20*G20 -> 0 | I20: 5400 | J20: =F20*I20 -> 3412800 | K20: 1200 | L20: =F20*K20 -> 758400 | M20: =+G20+I20+K20 -> 6600 | N20: =+H20+J20+L20 -> 4171200
C21: 수평규준틀 | E21: M2 | F21: 632 | G21: 1000 | H21: =F21*G21 -> 632000 | I21: 1500 | J21: =F21*I21 -> 948000 | L21: =F21*K21 -> 0 | M21: =+G21+I21+K21 -> 2500 | N21: =+H21+J21+L21 -> 1580000
C22: 먹매김 | E22: M2 | F22: 632 | G22: 1000 | H22: =F22*G22 -> 632000 | I22: 1500 | J22: =F22*I22 -> 948000 | L22: =F22*K22 -> 0 | M22: =+G22+I22+K22 -> 2500 | N22: =+H22+J22+L22 -> 1580000
C23: 조립말비계 | D23: 강관,6개월이하,1단 | E23: 조 | F23: 10 | G23: 45800 | H23: =F23*G23 -> 458000 | I23: 54100 | J23: =F23*I23 -> 541000 | L23: =F23*K23 -> 0 | M23: =+G23+I23+K23 -> 99900 | N23: =+H23+J23+L23 -> 999000
C24: 외부쌍줄비계 | D24: 외벽 발판두줄설치 | E24: M2 | F24: 1273 | G24: 7100 | H24: =F24*G24 -> 9038300 | I24: 7500 | J24: =F24*I24 -> 9547500 | K24: 800 | L24: =F24*K24 -> 1018400 | M24: =+G24+I24+K24 -> 15400 | N24: =+H24+J24+L24 -> 19604200
C25: 낙하물방지망 | E25: M2 | F25: 366 | G25: 2900 | H25: =F25*G25 -> 1061400 | I25: 2100 | J25: =F25*I25 -> 768600 | L25: =F25*K25 -> 0 | M25: =+G25+I25+K25 -> 5000 | N25: =+H25+J25+L25 -> 1830000
C26: 보호막설치 | D26: PE | E26: M2 | F26: 1273 | G26: 1700 | H26: =F26*G26 -> 2164100 | I26: 2100 | J26: =F26*I26 -> 2673300 | L26: =F26*K26 -> 0 | M26: =+G26+I26+K26 -> 3800 | N26: =+H26+J26+L26 -> 4837400
C27: 콘크리트면보양 | E27: M2 | F27: 632 | H27: =F27*G27 -> 0 | I27: 400 | J27: =F27*I27 -> 252800 | L27: =F27*K27 -> 0 | M27: =+G27+I27+K27 -> 400 | N27: =+H27+J27+L27 -> 252800
C28: 현장정리 | D28: 골조 | E28: M2 | F28: 632 | H28: =F28*G28 -> 0 | I28: 1700 | J28: =F28*I28 -> 1074400 | L28: =F28*K28 -> 0 | M28: =+G28+I28+K28 -> 1700 | N28: =+H28+J28+L28 -> 1074400
C29: 재해안전기술지도 | E29: EA | F29: 12 | H29: =F29*G29 -> 0 | K29: 166500 | L29: =F29*K29 -> 1998000 | M29: =+G29+I29+K29 -> 166500 | N29: =+H29+J29+L29 -> 1998000
L30: =F30*K30 -> 0 | M30: =+G30+I30+K30 -> 0 | N30: =+H30+J30+L30 -> 0
L31: =F31*K31 -> 0 | M31: =+G31+I31+K31 -> 0 | N31: =+H31+J31+L31 -> 0
C51: [ 합 계 ] | H51: =SUM(H5:H38) -> 17202500 | J51: =SUM(J5:J38) -> 22726800 | L51: =SUM(L5:L38) -> 25236900 | N51: =SUM(N5:N46) -> 65166200
C52: 0102 구조 보강 공사 (Dr. M PILE)
C53: 파일 코어천공 | E53: 개소 | F53: 44 | H53: =F53*G53 -> 0 | I53: 124900 | J53: =F53*I53 -> 5495600 | K53: 50000 | L53: =F53*K53 -> 2200000 | M53: =+G53+I53+K53 -> 174900 | N53: =+H53+J53+L53 -> 7695600
C54: Dr. HP PILE 설치 | E54: M | F54: 264 | G54: 50000 | H54: =F54*G54 -> 13200000 | I54: 25000 | J54: =F54*I54 -> 6600000 | K54: 16700 | L54: =F54*K54 -> 4408800 | M54: =+G54+I54+K54 -> 91700 | N54: =+H54+J54+L54 -> 24208800
C55: 영커 코어천공 및 설치 | E55: 개소 | F55: 44 | G55: 41600 | H55: =F55*G55 -> 1830400 | I55: 183200 | J55: =F55*I55 -> 8060800 | K55: 66600 | L55: =F55*K55 -> 2930400 | M55: =+G55+I55+K55 -> 291400 | N55: =+H55+J55+L55 -> 12821600
C56: 그라우팅 | D56: 속채움 | E56: M | F56: 264 | G56: 15000 | H56: =F56*G56 -> 3960000 | I56: 6700 | J56: =F56*I56 -> 1768800 | K56: 3300 | L56: =F56*K56 -> 871200 | M56: =+G56+I56+K56 -> 25000 | N56: =+H56+J56+L56 -> 6600000
C57: 정착판 설치 및 두부정리 | E57: 개소 | F57: 44 | G57: 99900 | H57: =F57*G57 -> 4395600 | I57: 74900 | J57: =F57*I57 -> 3295600 | K57: 16700 | L57: =F57*K57 -> 734800 | M57: =+G57+I57+K57 -> 191500 | N57: =+H57+J57+L57 -> 8426000
C58: 플랜트 설치 및 해체 | E58: 식 | F58: 1 | H58: =F58*G58 -> 0 | I58: 1665200 | J58: =F58*I58 -> 1665200 | K58: 6660900 | L58: =F58*K58 -> 6660900 | M58: =+G58+I58+K58 -> 8326100 | N58: =+H58+J58+L58 -> 8326100
C59: 압입장치 설치 및 해체 | E59: 식 | F59: 44 | H59: =F59*G59 -> 0 | I59: 74900 | J59: =F59*I59 -> 3295600 | K59: 50000 | L59: =F59*K59 -> 2200000 | M59: =+G59+I59+K59 -> 124900 | N59: =+H59+J59+L59 -> 5495600
...

Sheet 설비집계표
A1: 기 계 설 비 공 사 집 계 표
A3: =설비내역서!A3 -> [공사명 : 은평구 역촌동 36-9번지 근생 증축 및 대수선공사중 기계설비공사]
A4: 품 명 | B4: 규 격 | C4: 단위 | D4: 수량 | E4: 재 료 비 | G4: 노 무 비 | I4: 경 비 | K4: 합 계 | M4: 비 고
E5: 단 가 | F5: 금 액 | G5: 단 가 | H5: 금 액 | I5: 단 가 | J5: 금 액 | K5: 단 가 | L5: 금 액
A6: 0201 기계설비공사 | F6: =SUM(F7:F14) -> 41228080 | H6: =SUM(H7:H14) -> 33881420 | J6: =SUM(J7:J27) -> 0 | L6: =SUM(L7:L14) -> 75109500
A7: =설비내역서!A6 -> 0201 장비설치공사 | F7: =설비내역서!F27 -> 5037662 | H7: =설비내역서!H27 -> 2027900 | J7: =설비내역서!J6 -> 0 | L7: =F7+H7+J7 -> 7065562
A8: =설비내역서!A28 -> 0202 위생기구설치공사 | F8: =설비내역서!F49 -> 6881425 | H8: =설비내역서!H49 -> 4217500 | J8: =설비내역서!J28 -> 0 | L8: =F8+H8+J8 -> 11098925
A9: =설비내역서!A50 -> 0203 급수급탕배관공사 | F9: =설비내역서!F115 -> 4825056 | H9: =설비내역서!H115 -> 7028520 | J9: =설비내역서!J50 -> 0 | L9: =F9+H9+J9 -> 11853576
A10: =설비내역서!A116 -> 0204 오배수 및 환기배관공사 | F10: =설비내역서!F181 -> 6438546 | H10: =설비내역서!H181 -> 7316450 | J10: =설비내역서!J116 -> 0 | L10: =F10+H10+J10 -> 13754996
A11: =설비내역서!A204 -> 0206 난방배관공사 | F11: =설비내역서!F225 -> 854263 | H11: =설비내역서!H225 -> 2906500 | L11: =F11+H11+J11 -> 3760763
A12: =+설비내역서!A182 -> 0205 가스배관공사 | F12: =+설비내역서!F181 -> 6438546 | H12: =+설비내역서!H181 -> 7316450 | L12: =F12+H12+J12 -> 13754996
A13: =+설비내역서!A226 -> 0207 EHP,ERV 공사 | F13: =+설비내역서!F269 -> 10752582 | H13: =+설비내역서!H269 -> 3068100 | L13: =F13+H13+J13 -> 13820682
A15: 0202 소방설비공사 | F15: =SUM(F16:F19) -> 53333092 | H15: =SUM(H16:H19) -> 28175675 | I15: =SUM(I16:I19) -> 0 | L15: =SUM(L16:L19) -> 81508767
A16: =설비내역서!A270 -> 0201 소화장비설치공사 | F16: =설비내역서!F291 -> 23168508 | H16: =설비내역서!H291 -> 2313600 | L16: =F16+H16+J16 -> 25482108
A17: =설비내역서!A292 -> 0202 소화기계실배관공사 | F17: =설비내역서!F357 -> 6554620 | H17: =설비내역서!H357 -> 5202775 | L17: =F17+H17+J17 -> 11757395
A18: =설비내역서!A358 -> 0203 옥내소화배관공사 | F18: =설비내역서!F445 -> 20928564 | H18: =설비내역서!H445 -> 19422000 | L18: =F18+H18+J18 -> 40350564
A19: =설비내역서!A446 -> 0205 내진설치공사 | F19: =설비내역서!F467 -> 2681400 | H19: =설비내역서!H467 -> 1237300 | L19: =F19+H19+J19 -> 3918700
A27: 합 계 | F27: =+F15+F6 -> 94561172 | H27: =+H15+H6 -> 62057095 | L27: =+L15+L6 -> 156618267

Sheet 설비내역서
A1: 기 계 설 비 공 사 내 역 서
A3: [공사명 : 은평구 역촌동 36-9번지 근생 증축 및 대수선공사중 기계설비공사]
A4: 품 명 | B4: 규 격 | C4: 단위 | D4: 수량 | E4: 재 료 비 | G4: 노 무 비 | I4: 경 비 | K4: 합 계 | M4: 비 고
E5: 단 가 | F5: 금 액 | G5: 단 가 | H5: 금 액 | I5: 단 가 | J5: 금 액 | K5: 단 가 | L5: 금 액
A6: 0201 장비설치공사
A7: 배수펌프(수중형) | B7: 100L*6M*0.5HP | C7: EA | D7: 2 | E7: 158200 | F7: =D7*E7 -> 316400 | K7: =E7+G7+I7 -> 158200 | L7: =F7+H7+J7 -> 316400
A8: 온수보일러(가스) | B8: 20,000kcal/h | C8: EA | D8: 2 | E8: 582800 | F8: =D8*E8 -> 1165600 | K8: =E8+G8+I8 -> 582800 | L8: =F8+H8+J8 -> 1165600
A9: 배기휀(천정형,저소음) | B9: 3.5CMMx3.5mmAqx30W | C9: EA | D9: 7 | E9: 50000 | F9: =D9*E9 -> 350000 | K9: =E9+G9+I9 -> 50000 | L9: =F9+H9+J9 -> 350000
A10: 배기휀(천정형,저소음) | B10: 2CMMx1.5KW | C10: EA | D10: 3 | E10: 201500 | F10: =D10*E10 -> 604500 | K10: =E10+G10+I10 -> 201500 | L10: =F10+H10+J10 -> 604500
A11: 배기휀(라인형) | B11: 23CMMx10mmAqx0.1KW | C11: EA | D11: 1 | E11: 366300 | F11: =D11*E11 -> 366300 | K11: =E11+G11+I11 -> 366300 | L11: =F11+H11+J11 -> 366300
A12: 전기온수기(벽부형) | B12: 2.0KW | C12: EA | D12: 7 | E12: 192300 | F12: =D12*E12 -> 1346100 | K12: =E12+G12+I12 -> 192300 | L12: =F12+H12+J12 -> 1346100
A13: 복사난방기(천정형) | B13: 374KCAL | C13: EA | D13: 7 | E13: 119100 | F13: =D13*E13 -> 833700 | G13: 27500 | H13: =G13*D13 -> 192500 | K13: =E13+G13+I13 -> 146600 | L13: =F13+H13+J13 -> 1026200
A14: 노무비 | B14: 기계설비공 | C14: 인 | D14: 6 | F14: =D14*E14 -> 0 | G14: 226200 | H14: =G14*D14 -> 1357200 | K14: =E14+G14+I14 -> 226200 | L14: =F14+H14+J14 -> 1357200
A15: 노무비 | B15: 보통인부 | C15: 인 | D15: 3 | F15: =D15*E15 -> 0 | G15: 159400 | H15: =G15*D15 -> 478200 | K15: =E15+G15+I15 -> 159400 | L15: =F15+H15+J15 -> 478200
A16: 공구손료 | B16: 노무비의3% | C16: 식 | D16: 1 | E16: =TRUNC(SUM(H14:H15)*0.03,0) -> 55062 | F16: =D16*E16 -> 55062 | K16: =E16+G16+I16 -> 55062 | L16: =F16+H16+J16 -> 55062
A27: 합 계 | F27: =SUM(F7:F26) -> 5037662 | H27: =SUM(H7:H26) -> 2027900 | L27: =SUM(L7:L26) -> 7065562
A28: 0202 위생기구설치공사
A29: 양변기(LT) | C29: EA | D29: 10 | E29: 325100 | F29: =D29*E29 -> 3251000 | G29: 73300 | H29: =D29*G29 -> 733000 | K29: =E29+G29+I29 -> 398400 | L29: =F29+H29+J29 -> 3984000
A30: 세면기 | C30: EA | D30: 10 | E30: 247300 | F30: =D30*E30 -> 2473000 | G30: 73300 | H30: =G30*D30 -> 733000 | K30: =E30+G30+I30 -> 320600 | L30: =F30+H30+J30 -> 3206000
A31: 샤워기 | C31: EA | D31: 1 | E31: 274800 | F31: =D31*E31 -> 274800 | G31: 7300 | H31: =D31*G31 -> 7300 | K31: =E31+G31+I31 -> 282100 | L31: =F31+H31+J31 -> 282100
A32: 욕조수전 & 줄샤워기 겸용 | C32: EA | D32: 1 | E32: 108200 | F32: =D32*E32 -> 108200 | G32: 36600 | H32: =D32*G32 -> 36600 | K32: =E32+G32+I32 -> 144800 | L32: =F32+H32+J32 -> 144800
A33: 청소용 부동수전 | C33: EA | D33: 1 | E33: 20800 | F33: =D33*E33 -> 20800 | G33: 18300 | H33: =D33*G33 -> 18300 | K33: =E33+G33+I33 -> 39100 | L33: =F33+H33+J33 -> 39100
A34: 세탁수전 & 청소수전 겸용 | C34: EA | D34: 2 | E34: 25000 | F34: =D34*E34 -> 50000 | G34: 18300 | H34: =D34*G34 -> 36600 | K34: =E34+G34+I34 -> 43300 | L34: =F34+H34+J34 -> 86600
A35: 씽크수전 | C35: EA | D35: 2 | E35: 45800 | F35: =D35*E35 -> 91600 | G35: 18300 | H35: =D35*G35 -> 36600 | K35: =E35+G35+I35 -> 64100 | L35: =F35+H35+J35 -> 128200
A36: 휴지걸이 | C36: EA | D36: 10 | E36: 34800 | F36: =D36*E36 -> 348000 | G36: 7400 | H36: =D36*G36 -> 74000 | K36: =E36+G36+I36 -> 42200 | L36: =F36+H36+J36 -> 422000
A37: 비누갑 | B37: STS | C37: EA | D37: 10 | E37: 10000 | F37: =D37*E37 -> 100000 | G37: 7300 | H37: =D37*G37 -> 73000 | K37: =E37+G37+I37 -> 17300 | L37: =F37+H37+J37 -> 173000
A38: 수건걸이 | B38: STS | C38: EA | D38: 3 | E38: 12500 | F38: =D38*E38 -> 37500 | G38: 7300 | H38: =D38*G38 -> 21900 | K38: =E38+G38+I38 -> 19800 | L38: =F38+H38+J38 -> 59400
A39: 노무비 | B39: 위생공 | C39: 인 | D39: 8 | F39: =D39*E39 -> 0 | G39: 226200 | H39: =D39*G39 -> 1809600 | K39: =E39+G39+I39 -> 226200 | L39: =F39+H39+J39 -> 1809600
A40: 노무비 | B40: 보통인부 | C40: 인 | D40: 4 | F40: =D40*E40 -> 0 | G40: 159400 | H40: =D40*G40 -> 637600 | K40: =E40+G40+I40 -> 159400 | L40: =F40+H40+J40 -> 637600
A41: 공구손료 | B41: 노무비의 3% | C41: 식 | D41: 1 | E41: =TRUNC(SUM(H29:H40)*0.03,0) -> 126525 | F41: =D41*E41 -> 126525 | K41: =E41+G41+I41 -> 126525 | L41: =F41+H41+J41 -> 126525
A49: 합 계 | F49: =SUM(F29:F48) -> 6881425 | H49: =SUM(H29:H48) -> 4217500 | L49: =SUM(L29:L48) -> 11098925
A50: 0203 급수급탕배관공사
A51: STS배관(프레스식) | B51: D13 | C51: M | D51: 128 | E51: 1900 | F51: =D51*E51 -> 243200 | H51: =D51*G51 -> 0 | K51: =E51+G51+I51 -> 1900 | L51: =F51+H51+J51 -> 243200
A52: STS배관(프레스식) | B52: D20 | C52: M | D52: 181 | E52: 3200 | F52: =D52*E52 -> 579200 | H52: =D52*G52 -> 0 | K52: =E52+G52+I52 -> 3200 | L52: =F52+H52+J52 -> 579200
A53: STS배관(프레스식) | B53: D25 | C53: M | D53: 35 | E53: 4100 | F53: =D53*E53 -> 143500 | H53: =D53*G53 -> 0 | K53: =E53+G53+I53 -> 4100 | L53: =F53+H53+J53 -> 143500
A54: STS배관(프레스식) | B54: D30 | C54: M | D54: 28 | E54: 5600 | F54: =D54*E54 -> 156800 | H54: =D54*G54 -> 0 | K54: =E54+G54+I54 -> 5600 | L54: =F54+H54+J54 -> 156800
A55: 잡자재비 | B55: 관의3% | C55: 식 | D55: 1 | E55: =TRUNC(SUM(F51:F54)*0.03,0) -> 33681 | F55: =D55*E55 -> 33681 | H55: =D55*G55 -> 0 | K55: =E55+G55+I55 -> 33681 | L55: =F55+H55+J55 -> 33681
A56: 관보온(발포폴리에틸렌보온통) | B56: 25t × ø 15 | C56: m | D56: 122 | E56: 3100 | F56: =D56*E56 -> 378200 | G56: 3500 | H56: =D56*G56 -> 427000 | K56: =E56+G56+I56 -> 6600 | L56: =F56+H56+J56 -> 805200
A57: 관보온(발포폴리에틸렌보온통) | B57: 25t × ø 20 | C57: m | D57: 181 | E57: 3400 | F57: =D57*E57 -> 615400 | G57: 4100 | H57: =D57*G57 -> 742100 | K57: =E57+G57+I57 -> 7500 | L57: =F57+H57+J57 -> 1357500
A58: 관보온(발포폴리에틸렌보온통) | B58: 25t × ø 25 | C58: m | D58: 31 | E58: 3600 | F58: =D58*E58 -> 111600 | G58: 4500 | H58: =D58*G58 -> 139500 | K58: =E58+G58+I58 -> 8100 | L58: =F58+H58+J58 -> 251100
...

Sheet 전기총괄표
A1: [ 은평구역촌동36-9,증축및대수선공사 ]
A2: 공 종 명 | C2: 단위 | D2: 수량 | E2: 재료비 | I2: 경비 | K2: 계 | L2: 비고
E3: 단가 | F3: 금액 | G3: 단가 | H3: 금액 | I3: 단가 | J3: 금액
A4: [ 집 계 표 ]
A5: 3.전기공사
A6: 1.전력간선설비공사 | C6: 식 | D6: 1 | E6: =전기내역서!F66 -> 10895762 | F6: =D6*E6 -> 10895762 | G6: =전기내역서!H66 -> 4917220 | H6: =D6*G6 -> 4917220 | J6: =D6*I6 -> 0 | K6: =SUM(F6,H6,J6) -> 15812982
A7: 2.전등설비공사 | C7: 식 | D7: 1 | E7: =전기내역서!F108 -> 5030504 | F7: =D7*E7 -> 5030504 | G7: =전기내역서!H108 -> 8457330 | H7: =D7*G7 -> 8457330 | J7: =D7*I7 -> 0 | K7: =SUM(F7,H7,J7) -> 13487834
A8: 3.전열설비공사 | C8: 식 | D8: 1 | E8: =전기내역서!F129 -> 2178960 | F8: =D8*E8 -> 2178960 | G8: =전기내역서!H129 -> 4974900 | H8: =D8*G8 -> 4974900 | J8: =D8*I8 -> 0 | K8: =SUM(F8,H8,J8) -> 7153860
A9: 4.냉난방설비공사 | C9: 식 | D9: 1 | E9: =전기내역서!F150 -> 787900 | F9: =D9*E9 -> 787900 | G9: =전기내역서!H150 -> 1989960 | H9: =D9*G9 -> 1989960 | K9: =SUM(F9,H9,J9) -> 2777860
A10: ( 소 계 ) | F10: =SUM(F6:F9) -> 18893126 | H10: =SUM(H6:H9) -> 20339410 | K10: =SUM(K6:K9) -> 39232536
A11: 3-2.통신공사
A12: 1.정보통신 간선설비공사 | C12: 1 | D12: 식 | E12: =전기내역서!F192 -> 6975148 | F12: =C12*E12 -> 6975148 | G12: =전기내역서!H192 -> 6434822 | H12: =C12*G12 -> 6434822 | K12: =F12+H12 -> 13409970
A13: 2.정보통신 설비공사 | C13: 1 | D13: 식 | E13: =전기내역서!F213 -> 721994 | F13: =C13*E13 -> 721994 | G13: =전기내역서!H213 -> 6129118 | H13: =C13*G13 -> 6129118 | K13: =F13+H13 -> 6851112
A14: ( 소 계 ) | F14: =SUM(F12:F13) -> 7697142 | H14: =SUM(H12:H13) -> 12563940 | K14: =SUM(K12:K13) -> 20261082
A15: 3.-3소방공사
A16: 1.자동화재탐지설비공사 | C16: 1 | D16: 식 | E16: =전기내역서!F255 -> 5981169 | F16: =C16*E16 -> 5981169 | G16: =전기내역서!H255 -> 5472390 | H16: =C16*G16 -> 5472390 | K16: =F16+H16 -> 11453559
A17: 2.유도등설비공사 | C17: 1 | D17: 식 | E17: =전기내역서!F276 -> 936800 | F17: =C17*E17 -> 936800 | G17: =전기내역서!H276 -> 1989960 | H17: =C17*G17 -> 1989960 | K17: =F17+H17 -> 2926760
A18: ( 소 계 ) | F18: =SUM(F16:F17) -> 6917969 | H18: =SUM(H16:H17) -> 7462350 | K18: =SUM(K16:K17) -> 14380319
A20: 합 계 | F20: =+F18+F14+F10 -> 33508237 | H20: =+H18+H14+H10 -> 40365700 | K20: =+K18+K14+K10 -> 73873937

Sheet 전기내역서
A1: [ 은평구역촌동36-9,증축및대수선공사 ]
A2: 명 칭 | B2: 규 격 | C2: 단위 | D2: 수량 | E2: 재료비 | G2: 노무비 | I2: 경비 | K2: 계 | L2: 비고
E3: 단가 | F3: 금액 | G3: 단가 | H3: 금액 | I3: 단가 | J3: 금액
A4: 3.전기공사::1-1,전력간선설비공사
A5: 파상형 폴리에틸렌 전선관 | B5: 50㎜ | C5: m | D5: 40 | E5: 1800 | F5: =D5*E5 -> 72000 | K5: =F5 -> 72000
A6: 경질비닐전선관 | B6: HI 28 mm | C6: m | D6: 46 | E6: 1100 | F6: =D6*E6 -> 50600 | K6: =F6 -> 50600
A7: 경질비닐전선관 | B7: HI 36 mm | C7: m | D7: 42 | E7: 1400 | F7: =D7*E7 -> 58800 | K7: =F7 -> 58800
A8: 경질비닐전선관 | B8: HI 42 mm | C8: m | D8: 68 | E8: 1500 | F8: =D8*E8 -> 102000 | K8: =F8 -> 102000
A9: 경질비닐전선관 | B9: HI 54 mm | C9: m | D9: 36 | E9: 1700 | F9: =D9*E9 -> 61200 | K9: =F9 -> 61200
A10: 후렉시블전선관 | B10: GW 28mm | C10: m | D10: 8 | E10: 1800 | F10: =D10*E10 -> 14400 | K10: =F10 -> 14400
A11: 후렉시블전선관 | B11: GW 36mm | C11: m | D11: 8 | E11: 2700 | F11: =D11*E11 -> 21600 | K11: =F11 -> 21600
A12: 후렉시블전선관 | B12: GW 54mm | C12: m | D12: 12 | E12: 4800 | F12: =D12*E12 -> 57600 | K12: =F12 -> 57600
A13: 경질비닐전선관용 부품 | B13: 노말밴드, 28 mm | C13: 개 | D13: 4 | E13: 400 | F13: =D13*E13 -> 1600 | K13: =F13 -> 1600
A14: 경질비닐전선관용 부품 | B14: 노말밴드, 36 mm | C14: 개 | D14: 6 | E14: 600 | F14: =D14*E14 -> 3600 | K14: =F14 -> 3600
A15: 경질비닐전선관용 부품 | B15: 노말밴드, 42 mm | C15: 개 | D15: 8 | E15: 800 | F15: =D15*E15 -> 6400 | K15: =F15 -> 6400
A16: 경질비닐전선관용 부품 | B16: 노말밴드, 54 mm | C16: 개 | D16: 4 | E16: 1400 | F16: =D16*E16 -> 5600 | K16: =F16 -> 5600
... A45: 분전반 | B45: P-E/V | C45: 면 | D45: 1 | E45: 499600 | F45: =D45*E45 -> 499600 | K45: =F45 -> 499600
A46: 계량기함 | C46: 면 | D46: 1 | E46: 249800 | F46: =D46*E46 -> 249800 | K46: =F46 -> 249800
A47: 맨홀 | B47: 1000X1000X1000 | C47: 개 | D47: 1 | E47: 349700 | F47: =D47*E47 -> 349700 | K47: =F47 -> 349700
A48: [ 소모 잡자재 ] | B48: 전선, 전선관의 2 % | C48: 식 | D48: 1 | E48: =TRUNC(SUM(F5:F12,F20:F31)*0.02,0) -> 66962 | F48: =D48*E48 -> 66962 | K48: =F48 -> 66962
A49: 노 무 비 | B49: 내선전공 | C49: 인 | D49: 14 | G49: 241500 | H49: =D49*G49 -> 3381000 | K49: =SUM(H49) -> 3381000
A50: 노 무 비 | B50: 저압케이블공 | C50: 인 | D50: 5 | G50: 278600 | H50: =D50*G50 -> 1393000 | K50: =SUM(H50) -> 1393000
A51: [ 공 구 손 료 ] | B51: 노무비의 3 % | C51: 식 | D51: 1 | G51: =TRUNC(SUM(H49:H50)*0.03,0) -> 143220 | H51: =D51*G51 -> 143220 | K51: =SUM(H51) -> 143220
A66: ( 합 계 ) | F66: =SUM(F5:F65) -> 10895762 | H66: =SUM(H49:H65) -> 4917220 | K66: =SUM(K5:K65) -> 15812982
A67: 3.전기공사::1-2,전등설비공사
A68: 합성수지비닐전선관 | B68: CD 16 mm (난연성) | C68: m | D68: 1069 | E68: 100 | F68: =D68*E68 -> 106900 | K68: =F68 -> 106900
A69: 합성수지제 가요전선관 | B69: CD-난연성 22㎜ | C69: m | D69: 224 | E69: 300 | F69: =D69*E69 -> 67200 | K69: =F69 -> 67200
A70: 1종금속제가요전선관 | B70: 16 mm 일반-비방수 | C70: m | D70: 183 | E70: 400 | F70: =D70*E70 -> 73200 | K70: =F70 -> 73200
A71: 1종금속제가요전선관 | B71: 커넥터, 16 mm 일반-비방수 | C71: 개 | D71: 183 | E71: 300 | F71: =D71*E71 -> 54900 | K71: =F71 -> 54900
A72: 아우트렛박스 | B72: 8각 54㎜ | C72: 개 | D72: 152 | E72: 800 | F72: =D72*E72 -> 121600 | K72: =F72 -> 121600
A73: 아우트렛박스 | B73: 중형4각 54㎜ | C73: 개 | D73: 26 | E73: 1100 | F73: =D73*E73 -> 28600 | K73: =F73 -> 28600
A74: 스위치박스 | B74: 1 개용 54 mm | C74: 개 | D74: 26 | E74: 700 | F74: =D74*E74 -> 18200 | K74: =F74 -> 18200
A75: 스위치박스 | B75: 2 개용 54 mm | C75: 개 | D75: 12 | E75: 900 | F75: =D75*E75 -> 10800 | K75: =F75 -> 10800
A76: 아우트렛박스 커버 | B76: 커버, 8각, 평형 | C76: 개 | D76: 152 | E76: 400 | F76: =D76*E76 -> 60800 | K76: =F76 -> 60800
A77: 아우트렛박스 커버 | B77: 커버, 4각, 평형 | C77: 개 | D77: 12 | E77: 400 | F77: =D77*E77 -> 4800 | K77: =F77 -> 4800
A78: 450/750V 내열비닐절연전선 | B78: HFIX 1.78mm(2.5㎟) | C78: m | D78: 4476 | E78: 500 | F78: =D78*E78 -> 2238000 | K78: =F78 -> 2238000
A79: 스위치 | B79: 매입형 1로1구 | C79: 개 | D79: 8 | E79: 1700 | F79: =D79*E79 -> 13600 | K79: =F79 -> 13600
... A85: 콘센트 | B85: 노출접지형 1구 | C85: 개 | D85: 8 | E85: 1500 | F85: =D85*E85 -> 12000 | K85: =F85 -> 12000
A86: 와이어콘넥타 | C86: 개 | D86: 500 | E86: 100 | F86: =D86*E86 -> 50000 | K86: =F86 -> 50000
A87: 조명기구"A"TYPE | B87: LED50W 평판슬림매입등 | C87: 개 | D87: 52 | E87: 23300 | F87: =D87*E87 -> 1211600 | K87: =F87 -> 1211600
...
